Traceback (most recent call last):
  File "C:\Users\aelshall\AppData\Local\miniconda3\Lib\site-packages\nbclient\client.py", line 782, in _async_poll_for_reply
    msg = await ensure_async(self.kc.shell_channel.get_msg(timeout=new_timeout))
          ^^^^^^^^^^^^^^^^^^^^^^^^^^^^^^^^^^^^^^^^^^^^^^^^^^^^^^^^^^^^^^^^^^^^^^
  File "C:\Users\aelshall\AppData\Local\miniconda3\Lib\site-packages\jupyter_core\utils\__init__.py", line 198, in ensure_async
    result = await obj
             ^^^^^^^^^
  File "C:\Users\aelshall\AppData\Local\miniconda3\Lib\site-packages\jupyter_client\channels.py", line 313, in get_msg
    raise Empty
_queue.Empty

During handling of the above exception, another exception occurred:

Traceback (most recent call last):
  File "C:\Users\aelshall\AppData\Local\miniconda3\Lib\site-packages\jupyter_cache\executors\utils.py", line 58, in single_nb_execution
    executenb(
  File "C:\Users\aelshall\AppData\Local\miniconda3\Lib\site-packages\nbclient\client.py", line 1319, in execute
    return NotebookClient(nb=nb, resources=resources, km=km, **kwargs).execute()
           ^^^^^^^^^^^^^^^^^^^^^^^^^^^^^^^^^^^^^^^^^^^^^^^^^^^^^^^^^^^^^^^^^^^^^
  File "C:\Users\aelshall\AppData\Local\miniconda3\Lib\site-packages\jupyter_core\utils\__init__.py", line 165, in wrapped
    return loop.run_until_complete(inner)
           ^^^^^^^^^^^^^^^^^^^^^^^^^^^^^^
  File "C:\Users\aelshall\AppData\Local\miniconda3\Lib\asyncio\base_events.py", line 691, in run_until_complete
    return future.result()
           ^^^^^^^^^^^^^^^
  File "C:\Users\aelshall\AppData\Local\miniconda3\Lib\site-packages\nbclient\client.py", line 709, in async_execute
    await self.async_execute_cell(
  File "C:\Users\aelshall\AppData\Local\miniconda3\Lib\site-packages\nbclient\client.py", line 1005, in async_execute_cell
    exec_reply = await self.task_poll_for_reply
                 ^^^^^^^^^^^^^^^^^^^^^^^^^^^^^^
  File "C:\Users\aelshall\AppData\Local\miniconda3\Lib\site-packages\nbclient\client.py", line 806, in _async_poll_for_reply
    error_on_timeout_execute_reply = await self._async_handle_timeout(timeout, cell)
                                     ^^^^^^^^^^^^^^^^^^^^^^^^^^^^^^^^^^^^^^^^^^^^^^^
  File "C:\Users\aelshall\AppData\Local\miniconda3\Lib\site-packages\nbclient\client.py", line 856, in _async_handle_timeout
    raise CellTimeoutError.error_from_timeout_and_cell(
nbclient.exceptions.CellTimeoutError: A cell timed out while it was being executed, after 30 seconds.
The message was: Cell execution timed out.
Here is a preview of the cell contents:
-------------------
['# Function to calculate mean values over time', 'def calculate_time_series(image_collection, index_name):', '    # Inner function to reduce each image to a mean value over the AOI', '    def reduce_region(image):', '        # Calculate mean value for the specified index over the AOI']
...
['# Save data to CSV', "ndci_df.to_csv('NDCI_TimeSeries_BigCypress.csv', index=False)", "turbidity_df.to_csv('Turbidity_TimeSeries_BigCypress.csv', index=False)", "wvi_df.to_csv('WVI_TimeSeries_BigCypress.csv', index=False)", "merged_df.to_csv('Merged_TimeSeries_BigCypress.csv', index=False)"]
-------------------

