Traceback (most recent call last):
  File "C:\Users\aelshall\AppData\Local\miniconda3\Lib\site-packages\jupyter_cache\executors\utils.py", line 58, in single_nb_execution
    executenb(
  File "C:\Users\aelshall\AppData\Local\miniconda3\Lib\site-packages\nbclient\client.py", line 1319, in execute
    return NotebookClient(nb=nb, resources=resources, km=km, **kwargs).execute()
           ^^^^^^^^^^^^^^^^^^^^^^^^^^^^^^^^^^^^^^^^^^^^^^^^^^^^^^^^^^^^^^^^^^^^^
  File "C:\Users\aelshall\AppData\Local\miniconda3\Lib\site-packages\jupyter_core\utils\__init__.py", line 165, in wrapped
    return loop.run_until_complete(inner)
           ^^^^^^^^^^^^^^^^^^^^^^^^^^^^^^
  File "C:\Users\aelshall\AppData\Local\miniconda3\Lib\asyncio\base_events.py", line 691, in run_until_complete
    return future.result()
           ^^^^^^^^^^^^^^^
  File "C:\Users\aelshall\AppData\Local\miniconda3\Lib\site-packages\nbclient\client.py", line 709, in async_execute
    await self.async_execute_cell(
  File "C:\Users\aelshall\AppData\Local\miniconda3\Lib\site-packages\nbclient\client.py", line 1062, in async_execute_cell
    await self._check_raise_for_error(cell, cell_index, exec_reply)
  File "C:\Users\aelshall\AppData\Local\miniconda3\Lib\site-packages\nbclient\client.py", line 918, in _check_raise_for_error
    raise CellExecutionError.from_cell_and_msg(cell, exec_reply_content)
nbclient.exceptions.CellExecutionError: An error occurred while executing the following cell:
------------------
print(f"At {time_slot2[2]}, I {daily_activities2[2]}")
------------------


[31m---------------------------------------------------------------------------[39m
[31mIndexError[39m                                Traceback (most recent call last)
[36mCell[39m[36m [39m[32mIn[10][39m[32m, line 1[39m
[32m----> [39m[32m1[39m [38;5;28mprint[39m([33mf[39m[33m"[39m[33mAt [39m[38;5;132;01m{[39;00m[43mtime_slot2[49m[43m[[49m[32;43m2[39;49m[43m][49m[38;5;132;01m}[39;00m[33m, I [39m[38;5;132;01m{[39;00mdaily_activities2[[32m2[39m][38;5;132;01m}[39;00m[33m"[39m)

[31mIndexError[39m: list index out of range

