Traceback (most recent call last):
  File "C:\Users\aelshall\AppData\Local\miniconda3\Lib\site-packages\jupyter_cache\executors\utils.py", line 58, in single_nb_execution
    executenb(
  File "C:\Users\aelshall\AppData\Local\miniconda3\Lib\site-packages\nbclient\client.py", line 1319, in execute
    return NotebookClient(nb=nb, resources=resources, km=km, **kwargs).execute()
           ^^^^^^^^^^^^^^^^^^^^^^^^^^^^^^^^^^^^^^^^^^^^^^^^^^^^^^^^^^^^^^^^^^^^^
  File "C:\Users\aelshall\AppData\Local\miniconda3\Lib\site-packages\jupyter_core\utils\__init__.py", line 165, in wrapped
    return loop.run_until_complete(inner)
           ^^^^^^^^^^^^^^^^^^^^^^^^^^^^^^
  File "C:\Users\aelshall\AppData\Local\miniconda3\Lib\asyncio\base_events.py", line 691, in run_until_complete
    return future.result()
           ^^^^^^^^^^^^^^^
  File "C:\Users\aelshall\AppData\Local\miniconda3\Lib\site-packages\nbclient\client.py", line 709, in async_execute
    await self.async_execute_cell(
  File "C:\Users\aelshall\AppData\Local\miniconda3\Lib\site-packages\nbclient\client.py", line 1062, in async_execute_cell
    await self._check_raise_for_error(cell, cell_index, exec_reply)
  File "C:\Users\aelshall\AppData\Local\miniconda3\Lib\site-packages\nbclient\client.py", line 918, in _check_raise_for_error
    raise CellExecutionError.from_cell_and_msg(cell, exec_reply_content)
nbclient.exceptions.CellExecutionError: An error occurred while executing the following cell:
------------------
#Write your function here


# Call you function using these two numbers
x=8
y=2
results=math_operation(x,y)

# Print output

------------------


[31m---------------------------------------------------------------------------[39m
[31mNameError[39m                                 Traceback (most recent call last)
[36mCell[39m[36m [39m[32mIn[17][39m[32m, line 7[39m
[32m      5[39m x=[32m8[39m
[32m      6[39m y=[32m2[39m
[32m----> [39m[32m7[39m results=[43mmath_operation[49m(x,y)
[32m      9[39m [38;5;66;03m# Print output[39;00m

[31mNameError[39m: name 'math_operation' is not defined

