Traceback (most recent call last):
  File "C:\Users\aelshall\AppData\Local\miniconda3\Lib\site-packages\jupyter_cache\executors\utils.py", line 58, in single_nb_execution
    executenb(
  File "C:\Users\aelshall\AppData\Local\miniconda3\Lib\site-packages\nbclient\client.py", line 1319, in execute
    return NotebookClient(nb=nb, resources=resources, km=km, **kwargs).execute()
           ^^^^^^^^^^^^^^^^^^^^^^^^^^^^^^^^^^^^^^^^^^^^^^^^^^^^^^^^^^^^^^^^^^^^^
  File "C:\Users\aelshall\AppData\Local\miniconda3\Lib\site-packages\jupyter_core\utils\__init__.py", line 165, in wrapped
    return loop.run_until_complete(inner)
           ^^^^^^^^^^^^^^^^^^^^^^^^^^^^^^
  File "C:\Users\aelshall\AppData\Local\miniconda3\Lib\asyncio\base_events.py", line 691, in run_until_complete
    return future.result()
           ^^^^^^^^^^^^^^^
  File "C:\Users\aelshall\AppData\Local\miniconda3\Lib\site-packages\nbclient\client.py", line 709, in async_execute
    await self.async_execute_cell(
  File "C:\Users\aelshall\AppData\Local\miniconda3\Lib\site-packages\nbclient\client.py", line 1062, in async_execute_cell
    await self._check_raise_for_error(cell, cell_index, exec_reply)
  File "C:\Users\aelshall\AppData\Local\miniconda3\Lib\site-packages\nbclient\client.py", line 918, in _check_raise_for_error
    raise CellExecutionError.from_cell_and_msg(cell, exec_reply_content)
nbclient.exceptions.CellExecutionError: An error occurred while executing the following cell:
------------------
%load_ext jupyter_ai              
from ai_assistant import api_key  #Import api_key module  
api_key.set_API_key('OPENAI')     #Set API key for selected Provider: 'OPENAI' and 'ANTHROPIC'
------------------


[31m---------------------------------------------------------------------------[39m
[31mModuleNotFoundError[39m                       Traceback (most recent call last)
[36mCell[39m[36m [39m[32mIn[1][39m[32m, line 2[39m
[32m      1[39m get_ipython().run_line_magic([33m'[39m[33mload_ext[39m[33m'[39m, [33m'[39m[33mjupyter_ai[39m[33m'[39m)
[32m----> [39m[32m2[39m [38;5;28;01mfrom[39;00m[38;5;250m [39m[34;01mai_assistant[39;00m[38;5;250m [39m[38;5;28;01mimport[39;00m api_key  [38;5;66;03m#Import api_key module  [39;00m
[32m      3[39m api_key.set_API_key([33m'[39m[33mOPENAI[39m[33m'[39m)     [38;5;66;03m#Set API key for selected Provider: 'OPENAI' and 'ANTHROPIC'[39;00m

[31mModuleNotFoundError[39m: No module named 'ai_assistant'

