Traceback (most recent call last):
  File "C:\Users\aelshall\AppData\Local\miniconda3\Lib\site-packages\jupyter_cache\executors\utils.py", line 58, in single_nb_execution
    executenb(
  File "C:\Users\aelshall\AppData\Local\miniconda3\Lib\site-packages\nbclient\client.py", line 1305, in execute
    return NotebookClient(nb=nb, resources=resources, km=km, **kwargs).execute()
           ^^^^^^^^^^^^^^^^^^^^^^^^^^^^^^^^^^^^^^^^^^^^^^^^^^^^^^^^^^^^^^^^^^^^^
  File "C:\Users\aelshall\AppData\Local\miniconda3\Lib\site-packages\jupyter_core\utils\__init__.py", line 165, in wrapped
    return loop.run_until_complete(inner)
           ^^^^^^^^^^^^^^^^^^^^^^^^^^^^^^
  File "C:\Users\aelshall\AppData\Local\miniconda3\Lib\asyncio\base_events.py", line 653, in run_until_complete
    return future.result()
           ^^^^^^^^^^^^^^^
  File "C:\Users\aelshall\AppData\Local\miniconda3\Lib\site-packages\nbclient\client.py", line 705, in async_execute
    await self.async_execute_cell(
  File "C:\Users\aelshall\AppData\Local\miniconda3\Lib\site-packages\nbclient\client.py", line 1058, in async_execute_cell
    await self._check_raise_for_error(cell, cell_index, exec_reply)
  File "C:\Users\aelshall\AppData\Local\miniconda3\Lib\site-packages\nbclient\client.py", line 914, in _check_raise_for_error
    raise CellExecutionError.from_cell_and_msg(cell, exec_reply_content)
nbclient.exceptions.CellExecutionError: An error occurred while executing the following cell:
------------------
import ee
ee.Authenticate()
ee.Initialize()
------------------


[1;31m---------------------------------------------------------------------------[0m
[1;31mStdinNotImplementedError[0m                  Traceback (most recent call last)
Cell [1;32mIn[3], line 2[0m
[0;32m      1[0m [38;5;28;01mimport[39;00m [38;5;21;01mee[39;00m
[1;32m----> 2[0m [43mee[49m[38;5;241;43m.[39;49m[43mAuthenticate[49m[43m([49m[43m)[49m
[0;32m      3[0m ee[38;5;241m.[39mInitialize()

File [1;32m~\AppData\Local\miniconda3\Lib\site-packages\ee\__init__.py:124[0m, in [0;36mAuthenticate[1;34m(authorization_code, quiet, code_verifier, auth_mode, scopes, force)[0m
[0;32m     93[0m [38;5;28;01mdef[39;00m [38;5;21mAuthenticate[39m(
[0;32m     94[0m     authorization_code: Optional[[38;5;28mstr[39m] [38;5;241m=[39m [38;5;28;01mNone[39;00m,
[0;32m     95[0m     quiet: Optional[[38;5;28mbool[39m] [38;5;241m=[39m [38;5;28;01mNone[39;00m,
[1;32m   (...)[0m
[0;32m     99[0m     force: [38;5;28mbool[39m [38;5;241m=[39m [38;5;28;01mFalse[39;00m,
[0;32m    100[0m ) [38;5;241m-[39m[38;5;241m>[39m Optional[[38;5;28mbool[39m]:
[0;32m    101[0m [38;5;250m  [39m[38;5;124;03m"""Prompts the user to authorize access to Earth Engine via OAuth2.[39;00m
[0;32m    102[0m 
[0;32m    103[0m [38;5;124;03m  Args:[39;00m
[1;32m   (...)[0m
[0;32m    122[0m [38;5;124;03m    True if we found valid credentials and didn't run the auth flow.[39;00m
[0;32m    123[0m [38;5;124;03m  """[39;00m
[1;32m--> 124[0m   [38;5;28;01mreturn[39;00m [43moauth[49m[38;5;241;43m.[39;49m[43mauthenticate[49m[43m([49m[43mauthorization_code[49m[43m,[49m[43m [49m[43mquiet[49m[43m,[49m[43m [49m[43mcode_verifier[49m[43m,[49m[43m [49m[43mauth_mode[49m[43m,[49m
[0;32m    125[0m [43m                            [49m[43mscopes[49m[43m,[49m[43m [49m[43mforce[49m[43m)[49m

File [1;32m~\AppData\Local\miniconda3\Lib\site-packages\ee\oauth.py:512[0m, in [0;36mauthenticate[1;34m(cli_authorization_code, quiet, cli_code_verifier, auth_mode, scopes, force)[0m
[0;32m    509[0m [38;5;28;01mif[39;00m flow[38;5;241m.[39mdisplay_instructions(quiet):
[0;32m    510[0m   _open_new_browser(flow[38;5;241m.[39mauth_url)
[1;32m--> 512[0m [43mflow[49m[38;5;241;43m.[39;49m[43msave_code[49m[43m([49m[43m)[49m

File [1;32m~\AppData\Local\miniconda3\Lib\site-packages\ee\oauth.py:562[0m, in [0;36mFlow.save_code[1;34m(self, code)[0m
[0;32m    560[0m   redirect_uri [38;5;241m=[39m [38;5;28mself[39m[38;5;241m.[39mserver[38;5;241m.[39murl
[0;32m    561[0m   code [38;5;241m=[39m [38;5;28mself[39m[38;5;241m.[39mserver[38;5;241m.[39mfetch_code()  [38;5;66;03m# Waits for oauth callback[39;00m
[1;32m--> 562[0m [43m_obtain_and_write_token[49m[43m([49m[43mcode[49m[43m,[49m[43m [49m[38;5;28;43mself[39;49m[38;5;241;43m.[39;49m[43mcode_verifier[49m[43m,[49m[43m [49m[38;5;28;43mself[39;49m[38;5;241;43m.[39;49m[43mscopes[49m[43m,[49m[43m [49m[43mredirect_uri[49m[43m)[49m

File [1;32m~\AppData\Local\miniconda3\Lib\site-packages\ee\oauth.py:229[0m, in [0;36m_obtain_and_write_token[1;34m(auth_code, code_verifier, scopes, redirect_uri)[0m
[0;32m    227[0m   client_info[[38;5;124m'[39m[38;5;124mredirect_uri[39m[38;5;124m'[39m] [38;5;241m=[39m redirect_uri
[0;32m    228[0m [38;5;28;01mif[39;00m [38;5;129;01mnot[39;00m auth_code:
[1;32m--> 229[0m   auth_code [38;5;241m=[39m [38;5;28;43minput[39;49m[43m([49m[38;5;124;43m'[39;49m[38;5;124;43mEnter verification code: [39;49m[38;5;124;43m'[39;49m[43m)[49m
[0;32m    230[0m [38;5;28;01massert[39;00m [38;5;28misinstance[39m(auth_code, [38;5;28mstr[39m)
[0;32m    231[0m scopes [38;5;241m=[39m scopes [38;5;129;01mor[39;00m SCOPES

File [1;32m~\AppData\Local\miniconda3\Lib\site-packages\ipykernel\kernelbase.py:1269[0m, in [0;36mKernel.raw_input[1;34m(self, prompt)[0m
[0;32m   1267[0m [38;5;28;01mif[39;00m [38;5;129;01mnot[39;00m [38;5;28mself[39m[38;5;241m.[39m_allow_stdin:
[0;32m   1268[0m     msg [38;5;241m=[39m [38;5;124m"[39m[38;5;124mraw_input was called, but this frontend does not support input requests.[39m[38;5;124m"[39m
[1;32m-> 1269[0m     [38;5;28;01mraise[39;00m StdinNotImplementedError(msg)
[0;32m   1270[0m [38;5;28;01mreturn[39;00m [38;5;28mself[39m[38;5;241m.[39m_input_request(
[0;32m   1271[0m     [38;5;28mstr[39m(prompt),
[0;32m   1272[0m     [38;5;28mself[39m[38;5;241m.[39m_parent_ident[[38;5;124m"[39m[38;5;124mshell[39m[38;5;124m"[39m],
[0;32m   1273[0m     [38;5;28mself[39m[38;5;241m.[39mget_parent([38;5;124m"[39m[38;5;124mshell[39m[38;5;124m"[39m),
[0;32m   1274[0m     password[38;5;241m=[39m[38;5;28;01mFalse[39;00m,
[0;32m   1275[0m )

[1;31mStdinNotImplementedError[0m: raw_input was called, but this frontend does not support input requests.

