Traceback (most recent call last):
  File "C:\Users\aelshall\AppData\Local\miniconda3\Lib\site-packages\jupyter_cache\executors\utils.py", line 58, in single_nb_execution
    executenb(
  File "C:\Users\aelshall\AppData\Local\miniconda3\Lib\site-packages\nbclient\client.py", line 1305, in execute
    return NotebookClient(nb=nb, resources=resources, km=km, **kwargs).execute()
           ^^^^^^^^^^^^^^^^^^^^^^^^^^^^^^^^^^^^^^^^^^^^^^^^^^^^^^^^^^^^^^^^^^^^^
  File "C:\Users\aelshall\AppData\Local\miniconda3\Lib\site-packages\jupyter_core\utils\__init__.py", line 165, in wrapped
    return loop.run_until_complete(inner)
           ^^^^^^^^^^^^^^^^^^^^^^^^^^^^^^
  File "C:\Users\aelshall\AppData\Local\miniconda3\Lib\asyncio\base_events.py", line 653, in run_until_complete
    return future.result()
           ^^^^^^^^^^^^^^^
  File "C:\Users\aelshall\AppData\Local\miniconda3\Lib\site-packages\nbclient\client.py", line 705, in async_execute
    await self.async_execute_cell(
  File "C:\Users\aelshall\AppData\Local\miniconda3\Lib\site-packages\nbclient\client.py", line 1058, in async_execute_cell
    await self._check_raise_for_error(cell, cell_index, exec_reply)
  File "C:\Users\aelshall\AppData\Local\miniconda3\Lib\site-packages\nbclient\client.py", line 914, in _check_raise_for_error
    raise CellExecutionError.from_cell_and_msg(cell, exec_reply_content)
nbclient.exceptions.CellExecutionError: An error occurred while executing the following cell:
------------------
# Read image 
img = plt.imread('Data/Track026.png')
img_extent = (-90, -81, 23, 31) #lon E to W and Lat S to N

# Add image to map 
ax.imshow(img,              # Image to plot
          origin='upper',   # Origin is upper left corner for png image
          extent=img_extent, 
          transform=ccrs.PlateCarree(), # Specify coordinate system for image coordinates 
          zorder=12,        # Drawing order for image is above raster data but below land
         )

fig
------------------


[1;31m---------------------------------------------------------------------------[0m
[1;31mFileNotFoundError[0m                         Traceback (most recent call last)
Cell [1;32mIn[15], line 2[0m
[0;32m      1[0m [38;5;66;03m# Read image [39;00m
[1;32m----> 2[0m img [38;5;241m=[39m [43mplt[49m[38;5;241;43m.[39;49m[43mimread[49m[43m([49m[38;5;124;43m'[39;49m[38;5;124;43mData/Track026.png[39;49m[38;5;124;43m'[39;49m[43m)[49m
[0;32m      3[0m img_extent [38;5;241m=[39m ([38;5;241m-[39m[38;5;241m90[39m, [38;5;241m-[39m[38;5;241m81[39m, [38;5;241m23[39m, [38;5;241m31[39m) [38;5;66;03m#lon E to W and Lat S to N[39;00m
[0;32m      5[0m [38;5;66;03m# Add image to map [39;00m

File [1;32m~\AppData\Local\miniconda3\Lib\site-packages\matplotlib\pyplot.py:2404[0m, in [0;36mimread[1;34m(fname, format)[0m
[0;32m   2400[0m [38;5;129m@_copy_docstring_and_deprecators[39m(matplotlib[38;5;241m.[39mimage[38;5;241m.[39mimread)
[0;32m   2401[0m [38;5;28;01mdef[39;00m [38;5;21mimread[39m(
[0;32m   2402[0m         fname: [38;5;28mstr[39m [38;5;241m|[39m pathlib[38;5;241m.[39mPath [38;5;241m|[39m BinaryIO, [38;5;28mformat[39m: [38;5;28mstr[39m [38;5;241m|[39m [38;5;28;01mNone[39;00m [38;5;241m=[39m [38;5;28;01mNone[39;00m
[0;32m   2403[0m ) [38;5;241m-[39m[38;5;241m>[39m np[38;5;241m.[39mndarray:
[1;32m-> 2404[0m     [38;5;28;01mreturn[39;00m [43mmatplotlib[49m[38;5;241;43m.[39;49m[43mimage[49m[38;5;241;43m.[39;49m[43mimread[49m[43m([49m[43mfname[49m[43m,[49m[43m [49m[38;5;28;43mformat[39;49m[43m)[49m

File [1;32m~\AppData\Local\miniconda3\Lib\site-packages\matplotlib\image.py:1525[0m, in [0;36mimread[1;34m(fname, format)[0m
[0;32m   1518[0m [38;5;28;01mif[39;00m [38;5;28misinstance[39m(fname, [38;5;28mstr[39m) [38;5;129;01mand[39;00m [38;5;28mlen[39m(parse[38;5;241m.[39murlparse(fname)[38;5;241m.[39mscheme) [38;5;241m>[39m [38;5;241m1[39m:
[0;32m   1519[0m     [38;5;66;03m# Pillow doesn't handle URLs directly.[39;00m
[0;32m   1520[0m     [38;5;28;01mraise[39;00m [38;5;167;01mValueError[39;00m(
[0;32m   1521[0m         [38;5;124m"[39m[38;5;124mPlease open the URL for reading and pass the [39m[38;5;124m"[39m
[0;32m   1522[0m         [38;5;124m"[39m[38;5;124mresult to Pillow, e.g. with [39m[38;5;124m"[39m
[0;32m   1523[0m         [38;5;124m"[39m[38;5;124m``np.array(PIL.Image.open(urllib.request.urlopen(url)))``.[39m[38;5;124m"[39m
[0;32m   1524[0m         )
[1;32m-> 1525[0m [38;5;28;01mwith[39;00m [43mimg_open[49m[43m([49m[43mfname[49m[43m)[49m [38;5;28;01mas[39;00m image:
[0;32m   1526[0m     [38;5;28;01mreturn[39;00m (_pil_png_to_float_array(image)
[0;32m   1527[0m             [38;5;28;01mif[39;00m [38;5;28misinstance[39m(image, PIL[38;5;241m.[39mPngImagePlugin[38;5;241m.[39mPngImageFile) [38;5;28;01melse[39;00m
[0;32m   1528[0m             pil_to_array(image))

File [1;32m~\AppData\Local\miniconda3\Lib\site-packages\PIL\ImageFile.py:125[0m, in [0;36mImageFile.__init__[1;34m(self, fp, filename)[0m
[0;32m    121[0m [38;5;28mself[39m[38;5;241m.[39mdecodermaxblock [38;5;241m=[39m MAXBLOCK
[0;32m    123[0m [38;5;28;01mif[39;00m is_path(fp):
[0;32m    124[0m     [38;5;66;03m# filename[39;00m
[1;32m--> 125[0m     [38;5;28mself[39m[38;5;241m.[39mfp [38;5;241m=[39m [38;5;28;43mopen[39;49m[43m([49m[43mfp[49m[43m,[49m[43m [49m[38;5;124;43m"[39;49m[38;5;124;43mrb[39;49m[38;5;124;43m"[39;49m[43m)[49m
[0;32m    126[0m     [38;5;28mself[39m[38;5;241m.[39mfilename [38;5;241m=[39m fp
[0;32m    127[0m     [38;5;28mself[39m[38;5;241m.[39m_exclusive_fp [38;5;241m=[39m [38;5;28;01mTrue[39;00m

[1;31mFileNotFoundError[0m: [Errno 2] No such file or directory: 'Data/Track026.png'

