Traceback (most recent call last):
  File "C:\Users\aelshall\AppData\Local\miniconda3\Lib\site-packages\jupyter_cache\executors\utils.py", line 58, in single_nb_execution
    executenb(
  File "C:\Users\aelshall\AppData\Local\miniconda3\Lib\site-packages\nbclient\client.py", line 1305, in execute
    return NotebookClient(nb=nb, resources=resources, km=km, **kwargs).execute()
           ^^^^^^^^^^^^^^^^^^^^^^^^^^^^^^^^^^^^^^^^^^^^^^^^^^^^^^^^^^^^^^^^^^^^^
  File "C:\Users\aelshall\AppData\Local\miniconda3\Lib\site-packages\jupyter_core\utils\__init__.py", line 165, in wrapped
    return loop.run_until_complete(inner)
           ^^^^^^^^^^^^^^^^^^^^^^^^^^^^^^
  File "C:\Users\aelshall\AppData\Local\miniconda3\Lib\asyncio\base_events.py", line 653, in run_until_complete
    return future.result()
           ^^^^^^^^^^^^^^^
  File "C:\Users\aelshall\AppData\Local\miniconda3\Lib\site-packages\nbclient\client.py", line 705, in async_execute
    await self.async_execute_cell(
  File "C:\Users\aelshall\AppData\Local\miniconda3\Lib\site-packages\nbclient\client.py", line 1058, in async_execute_cell
    await self._check_raise_for_error(cell, cell_index, exec_reply)
  File "C:\Users\aelshall\AppData\Local\miniconda3\Lib\site-packages\nbclient\client.py", line 914, in _check_raise_for_error
    raise CellExecutionError.from_cell_and_msg(cell, exec_reply_content)
nbclient.exceptions.CellExecutionError: An error occurred while executing the following cell:
------------------
# Define a Python list containing two sublists representing rows of data
data = [[2, 4, 6, 8, 10],
        [0, 10, 20, 30, 40]]

# Convert the Python list 'data' to a NumPy array and assign it to the variable 'np_array'


# Print array type, shape, and values
print(np_array.dtype, np_array.shape)
print(np_array)
------------------


[1;31m---------------------------------------------------------------------------[0m
[1;31mNameError[0m                                 Traceback (most recent call last)
Cell [1;32mIn[7], line 9[0m
[0;32m      2[0m data [38;5;241m=[39m [[[38;5;241m2[39m, [38;5;241m4[39m, [38;5;241m6[39m, [38;5;241m8[39m, [38;5;241m10[39m],
[0;32m      3[0m         [[38;5;241m0[39m, [38;5;241m10[39m, [38;5;241m20[39m, [38;5;241m30[39m, [38;5;241m40[39m]]
[0;32m      5[0m [38;5;66;03m# Convert the Python list 'data' to a NumPy array and assign it to the variable 'np_array'[39;00m
[0;32m      6[0m 
[0;32m      7[0m 
[0;32m      8[0m [38;5;66;03m# Print array type, shape, and values[39;00m
[1;32m----> 9[0m [38;5;28mprint[39m([43mnp_array[49m[38;5;241m.[39mdtype, np_array[38;5;241m.[39mshape)
[0;32m     10[0m [38;5;28mprint[39m(np_array)

[1;31mNameError[0m: name 'np_array' is not defined

