Traceback (most recent call last):
  File "C:\Python311\Lib\site-packages\jupyter_cache\executors\utils.py", line 58, in single_nb_execution
    executenb(
  File "C:\Python311\Lib\site-packages\nbclient\client.py", line 1314, in execute
    return NotebookClient(nb=nb, resources=resources, km=km, **kwargs).execute()
           ^^^^^^^^^^^^^^^^^^^^^^^^^^^^^^^^^^^^^^^^^^^^^^^^^^^^^^^^^^^^^^^^^^^^^
  File "C:\Python311\Lib\site-packages\jupyter_core\utils\__init__.py", line 165, in wrapped
    return loop.run_until_complete(inner)
           ^^^^^^^^^^^^^^^^^^^^^^^^^^^^^^
  File "C:\Python311\Lib\asyncio\base_events.py", line 650, in run_until_complete
    return future.result()
           ^^^^^^^^^^^^^^^
  File "C:\Python311\Lib\contextlib.py", line 222, in __aexit__
    await self.gen.athrow(typ, value, traceback)
  File "C:\Python311\Lib\site-packages\nbclient\client.py", line 654, in async_setup_kernel
    yield
  File "C:\Python311\Lib\site-packages\nbclient\client.py", line 709, in async_execute
    await self.async_execute_cell(
  File "C:\Python311\Lib\site-packages\nbclient\client.py", line 1062, in async_execute_cell
    await self._check_raise_for_error(cell, cell_index, exec_reply)
  File "C:\Python311\Lib\site-packages\nbclient\client.py", line 918, in _check_raise_for_error
    raise CellExecutionError.from_cell_and_msg(cell, exec_reply_content)
nbclient.exceptions.CellExecutionError: An error occurred while executing the following cell:
------------------
tempCelsius=float(temp_celsius)
tempFahrenheit = 9 / 5 * temp_celsius + 32
print(tempFahrenheit)
------------------


[1;31m---------------------------------------------------------------------------[0m
[1;31mNameError[0m                                 Traceback (most recent call last)
Cell [1;32mIn[10], line 1[0m
[1;32m----> 1[0m tempCelsius[38;5;241m=[39m[38;5;28mfloat[39m([43mtemp_celsius[49m)
[0;32m      2[0m tempFahrenheit [38;5;241m=[39m [38;5;241m9[39m [38;5;241m/[39m [38;5;241m5[39m [38;5;241m*[39m temp_celsius [38;5;241m+[39m [38;5;241m32[39m
[0;32m      3[0m [38;5;28mprint[39m(tempFahrenheit)

[1;31mNameError[0m: name 'temp_celsius' is not defined

