Traceback (most recent call last):
  File "C:\Python311\Lib\site-packages\jupyter_cache\executors\utils.py", line 58, in single_nb_execution
    executenb(
  File "C:\Python311\Lib\site-packages\nbclient\client.py", line 1314, in execute
    return NotebookClient(nb=nb, resources=resources, km=km, **kwargs).execute()
           ^^^^^^^^^^^^^^^^^^^^^^^^^^^^^^^^^^^^^^^^^^^^^^^^^^^^^^^^^^^^^^^^^^^^^
  File "C:\Python311\Lib\site-packages\jupyter_core\utils\__init__.py", line 165, in wrapped
    return loop.run_until_complete(inner)
           ^^^^^^^^^^^^^^^^^^^^^^^^^^^^^^
  File "C:\Python311\Lib\asyncio\base_events.py", line 650, in run_until_complete
    return future.result()
           ^^^^^^^^^^^^^^^
  File "C:\Python311\Lib\contextlib.py", line 222, in __aexit__
    await self.gen.athrow(typ, value, traceback)
  File "C:\Python311\Lib\site-packages\nbclient\client.py", line 654, in async_setup_kernel
    yield
  File "C:\Python311\Lib\site-packages\nbclient\client.py", line 709, in async_execute
    await self.async_execute_cell(
  File "C:\Python311\Lib\site-packages\nbclient\client.py", line 1062, in async_execute_cell
    await self._check_raise_for_error(cell, cell_index, exec_reply)
  File "C:\Python311\Lib\site-packages\nbclient\client.py", line 918, in _check_raise_for_error
    raise CellExecutionError.from_cell_and_msg(cell, exec_reply_content)
nbclient.exceptions.CellExecutionError: An error occurred while executing the following cell:
------------------
# Load a Landsat image
image = ee.Image('LANDSAT/LC08/C01/T1_TOA/LC08_044034_20140318')

# Define visualization parameters
vis_params = {
    'bands': ['B4', 'B3', 'B2'],
    'max': 0.3
}

import folium

# Center the map on the image
map_center = image.geometry().centroid().getInfo()['coordinates'][::-1]

# Create a folium map
mymap = folium.Map(location=map_center, zoom_start=10)
mymap.add_ee_layer(image, vis_params, 'Landsat image')

# Display the map
mymap
------------------


[1;31m---------------------------------------------------------------------------[0m
[1;31mNameError[0m                                 Traceback (most recent call last)
Cell [1;32mIn[1], line 2[0m
[0;32m      1[0m [38;5;66;03m# Load a Landsat image[39;00m
[1;32m----> 2[0m image [38;5;241m=[39m [43mee[49m[38;5;241m.[39mImage([38;5;124m'[39m[38;5;124mLANDSAT/LC08/C01/T1_TOA/LC08_044034_20140318[39m[38;5;124m'[39m)
[0;32m      4[0m [38;5;66;03m# Define visualization parameters[39;00m
[0;32m      5[0m vis_params [38;5;241m=[39m {
[0;32m      6[0m     [38;5;124m'[39m[38;5;124mbands[39m[38;5;124m'[39m: [[38;5;124m'[39m[38;5;124mB4[39m[38;5;124m'[39m, [38;5;124m'[39m[38;5;124mB3[39m[38;5;124m'[39m, [38;5;124m'[39m[38;5;124mB2[39m[38;5;124m'[39m],
[0;32m      7[0m     [38;5;124m'[39m[38;5;124mmax[39m[38;5;124m'[39m: [38;5;241m0.3[39m
[0;32m      8[0m }

[1;31mNameError[0m: name 'ee' is not defined

