Traceback (most recent call last):
  File "C:\Users\aelshall\AppData\Local\miniconda3\Lib\site-packages\jupyter_cache\executors\utils.py", line 58, in single_nb_execution
    executenb(
  File "C:\Users\aelshall\AppData\Local\miniconda3\Lib\site-packages\nbclient\client.py", line 1319, in execute
    return NotebookClient(nb=nb, resources=resources, km=km, **kwargs).execute()
           ^^^^^^^^^^^^^^^^^^^^^^^^^^^^^^^^^^^^^^^^^^^^^^^^^^^^^^^^^^^^^^^^^^^^^
  File "C:\Users\aelshall\AppData\Local\miniconda3\Lib\site-packages\jupyter_core\utils\__init__.py", line 165, in wrapped
    return loop.run_until_complete(inner)
           ^^^^^^^^^^^^^^^^^^^^^^^^^^^^^^
  File "C:\Users\aelshall\AppData\Local\miniconda3\Lib\asyncio\base_events.py", line 691, in run_until_complete
    return future.result()
           ^^^^^^^^^^^^^^^
  File "C:\Users\aelshall\AppData\Local\miniconda3\Lib\site-packages\nbclient\client.py", line 709, in async_execute
    await self.async_execute_cell(
  File "C:\Users\aelshall\AppData\Local\miniconda3\Lib\site-packages\nbclient\client.py", line 1062, in async_execute_cell
    await self._check_raise_for_error(cell, cell_index, exec_reply)
  File "C:\Users\aelshall\AppData\Local\miniconda3\Lib\site-packages\nbclient\client.py", line 918, in _check_raise_for_error
    raise CellExecutionError.from_cell_and_msg(cell, exec_reply_content)
nbclient.exceptions.CellExecutionError: An error occurred while executing the following cell:
------------------
# Load a Landsat image
image = ee.Image('LANDSAT/LC08/C01/T1_TOA/LC08_044034_20140318')

# Define visualization parameters
vis_params = {
    'bands': ['B4', 'B3', 'B2'],
    'max': 0.3
}

import folium

# Center the map on the image
map_center = image.geometry().centroid().getInfo()['coordinates'][::-1]

# Create a folium map
mymap = folium.Map(location=map_center, zoom_start=10)
mymap.add_ee_layer(image, vis_params, 'Landsat image')

# Display the map
mymap
------------------


[31m---------------------------------------------------------------------------[39m
[31mNameError[39m                                 Traceback (most recent call last)
[36mCell[39m[36m [39m[32mIn[1][39m[32m, line 2[39m
[32m      1[39m [38;5;66;03m# Load a Landsat image[39;00m
[32m----> [39m[32m2[39m image = [43mee[49m.Image([33m'[39m[33mLANDSAT/LC08/C01/T1_TOA/LC08_044034_20140318[39m[33m'[39m)
[32m      4[39m [38;5;66;03m# Define visualization parameters[39;00m
[32m      5[39m vis_params = {
[32m      6[39m     [33m'[39m[33mbands[39m[33m'[39m: [[33m'[39m[33mB4[39m[33m'[39m, [33m'[39m[33mB3[39m[33m'[39m, [33m'[39m[33mB2[39m[33m'[39m],
[32m      7[39m     [33m'[39m[33mmax[39m[33m'[39m: [32m0.3[39m
[32m      8[39m }

[31mNameError[39m: name 'ee' is not defined

